<?xml version="1.0"?>

<robot xmlns:xacro="http://www.ros.org/wiki/xacro">

<xacro:macro name="spherical" params="name parent child x y z *origin">

    <joint name="${name}_y" type="revolute">
      <xacro:insert_block name="origin" />
      <axis xyz="0 ${y} 0" />
      <limit effort="1000.0" lower="-3.14" upper="3.14" velocity="0.5"/>
      <parent link="${parent}"/>
      <child link="${name}_virt_link_1"/>
    </joint>

    <link name="${name}_virt_link_1">
      <inertial>
        <mass value="0.025" />
        <inertia ixx="5.8083e-4" ixy="0" ixz="0" iyy="3.0833e-5" iyz="0" izz="5.9083e-4" />
      </inertial>
    </link>

    <xacro:if value="${x == 'fixed'}">
      <joint name="${name}_x" type="fixed">
        <parent link="${name}_virt_link_1"/>
        <child link="${name}_virt_link_2"/>
      </joint>
    </xacro:if>

    <xacro:unless value="${x == 'fixed'}">
      <joint name="${name}_x" type="revolute">
        <axis xyz="${x} 0 0" />
        <limit effort="1000.0" lower="-3.14" upper="3.14" velocity="0.5"/>
        <parent link="${name}_virt_link_1"/>
        <child link="${name}_virt_link_2"/>
      </joint>
    </xacro:unless>

    <link name="${name}_virt_link_2">
      <inertial>
        <mass value="0.025" />
        <inertia ixx="5.8083e-4" ixy="0" ixz="0" iyy="3.0833e-5" iyz="0" izz="5.9083e-4" />
      </inertial>
    </link>


    <joint name="${name}_z" type="revolute">
      <axis xyz="0 0 ${z}" />
      <limit effort="1000.0" lower="-3.14" upper="3.14" velocity="0.5"/>
      <parent link="${name}_virt_link_2"/>
      <child link="${name}_virt_link_3"/>
    </joint>

    <link name="${name}_virt_link_3">
      <inertial>
        <mass value="0.025" />
        <inertia ixx="5.8083e-4" ixy="0" ixz="0" iyy="3.0833e-5" iyz="0" izz="5.9083e-4" />
      </inertial>
    </link>


    <joint name="${name}_F" type="fixed">
      <parent link="${name}_virt_link_3"/>
      <child link="${child}"/>
    </joint>
</xacro:macro>

</robot>
